I'm sorry, but an uncaught exception occurred.

While running game code:
  File "game/script.rpy", line 40, in script
    init python:
  File "game/script.rpy", line 227, in <module>
    day_start()
  File "game/script.rpy", line 221, in day_start
    update_apartment_state('game_files/apt_day_' + day + '.csv', store.apartment_data, store.game_state)
  File "game/script.rpy", line 183, in update_apartment_state
    story_object['image'] = get_apartment_image(row['IMAGE_FOLDER'], row['IMAGE'])
NameError: name 'get_apartment_image' is not defined

-- Full Traceback ------------------------------------------------------------

Full traceback:
  File "game/script.rpy", line 40, in script
    init python:
  File "/home/brent/dataville-renpy/renpy-8.1.3-sdk/renpy/ast.py", line 1138, in execute
    renpy.python.py_exec_bytecode(self.code.bytecode, self.hide, store=self.store)
  File "/home/brent/dataville-renpy/renpy-8.1.3-sdk/renpy/python.py", line 1122, in py_exec_bytecode
    exec(bytecode, globals, locals)
  File "game/script.rpy", line 227, in <module>
    day_start()
  File "game/script.rpy", line 221, in day_start
    update_apartment_state('game_files/apt_day_' + day + '.csv', store.apartment_data, store.game_state)
  File "game/script.rpy", line 183, in update_apartment_state
    story_object['image'] = get_apartment_image(row['IMAGE_FOLDER'], row['IMAGE'])
NameError: name 'get_apartment_image' is not defined

Linux-6.2.0-39-generic-x86_64-with-glibc2.35 x86_64
Ren'Py 8.1.3.23091805
DataVille 1.0
Mon Jan  1 17:11:51 2024
