I'm sorry, but an uncaught exception occurred.

While running game code:
  File "game/script.rpy", line 520, in script call
    else:
  File "game/script.rpy", line 520, in script call
    else:
  File "game/script.rpy", line 520, in script call
    else:
  [Previous line repeated 2 more times]
  File "game/script.rpy", line 518, in script call
    $ day_end()
  File "game/script.rpy", line 555, in script call
    "Sleeping, day [store.game_state.day]..."
  File "game/script.rpy", line 560, in script call
    $ cleaned = clean(store.apartment_data)
  File "game/script.rpy", line 520, in script call
    else:
  File "game/script.rpy", line 499, in script
    call screen expression(task['type']) pass (task)
  File "game/script.rpy", line 510, in <module>
    else:
  File "game/script.rpy", line 335, in check_binary
    if value == task['correct_options']:
KeyError: 'correct_options'

-- Full Traceback ------------------------------------------------------------

Full traceback:
  File "game/script.rpy", line 520, in script call
    else:
  File "game/script.rpy", line 520, in script call
    else:
  File "game/script.rpy", line 520, in script call
    else:
  [Previous line repeated 2 more times]
  File "game/script.rpy", line 518, in script call
    $ day_end()
  File "game/script.rpy", line 555, in script call
    "Sleeping, day [store.game_state.day]..."
  File "game/script.rpy", line 560, in script call
    $ cleaned = clean(store.apartment_data)
  File "game/script.rpy", line 520, in script call
    else:
  File "game/script.rpy", line 499, in script
    call screen expression(task['type']) pass (task)
  File "/home/brent/dataville-renpy/renpy-8.1.3-sdk/renpy/ast.py", line 1138, in execute
    renpy.python.py_exec_bytecode(self.code.bytecode, self.hide, store=self.store)
  File "/home/brent/dataville-renpy/renpy-8.1.3-sdk/renpy/python.py", line 1122, in py_exec_bytecode
    exec(bytecode, globals, locals)
  File "game/script.rpy", line 510, in <module>
    else:
  File "game/script.rpy", line 335, in check_binary
    if value == task['correct_options']:
KeyError: 'correct_options'

Linux-6.2.0-39-generic-x86_64-with-glibc2.35 x86_64
Ren'Py 8.1.3.23091805
DataVille 1.0
Tue Dec 26 17:09:06 2023
