I'm sorry, but an uncaught exception occurred.

While running game code:
  File "game/script.rpy", line 447, in script
    python:
  File "game/script.rpy", line 459, in <module>
    task = update_state(store.game_state, binary_correct, task)
  File "game/script.rpy", line 284, in update_state
    return set_ui_state(next_Task, state, performance_text, reward)
NameError: name 'next_Task' is not defined

-- Full Traceback ------------------------------------------------------------

Full traceback:
  File "game/script.rpy", line 447, in script
    python:
  File "/home/brent/dataville-renpy/renpy-8.1.3-sdk/renpy/ast.py", line 1138, in execute
    renpy.python.py_exec_bytecode(self.code.bytecode, self.hide, store=self.store)
  File "/home/brent/dataville-renpy/renpy-8.1.3-sdk/renpy/python.py", line 1122, in py_exec_bytecode
    exec(bytecode, globals, locals)
  File "game/script.rpy", line 459, in <module>
    task = update_state(store.game_state, binary_correct, task)
  File "game/script.rpy", line 284, in update_state
    return set_ui_state(next_Task, state, performance_text, reward)
NameError: name 'next_Task' is not defined

Linux-6.2.0-39-generic-x86_64-with-glibc2.35 x86_64
Ren'Py 8.1.3.23091805
DataVille 1.0
Mon Jan  1 13:41:03 2024
