I'm sorry, but an uncaught exception occurred.

While running game code:
  File "game/script.rpy", line 534, in script call
    call task_loop
  File "game/script.rpy", line 534, in script call
    call task_loop
  File "game/script.rpy", line 534, in script call
    call task_loop
  [Previous line repeated 2 more times]
  File "game/script.rpy", line 514, in script
    python:
  File "game/script.rpy", line 526, in <module>
    task = update_state(store.game_state, binary_correct, task)
  File "game/script.rpy", line 257, in update_state
    if ('event_flag_dependency' in next_task):
UnboundLocalError: local variable 'next_task' referenced before assignment

-- Full Traceback ------------------------------------------------------------

Full traceback:
  File "game/script.rpy", line 534, in script call
    call task_loop
  File "game/script.rpy", line 534, in script call
    call task_loop
  File "game/script.rpy", line 534, in script call
    call task_loop
  [Previous line repeated 2 more times]
  File "game/script.rpy", line 514, in script
    python:
  File "/home/brent/dataville-renpy/renpy-8.1.3-sdk/renpy/ast.py", line 1138, in execute
    renpy.python.py_exec_bytecode(self.code.bytecode, self.hide, store=self.store)
  File "/home/brent/dataville-renpy/renpy-8.1.3-sdk/renpy/python.py", line 1122, in py_exec_bytecode
    exec(bytecode, globals, locals)
  File "game/script.rpy", line 526, in <module>
    task = update_state(store.game_state, binary_correct, task)
  File "game/script.rpy", line 257, in update_state
    if ('event_flag_dependency' in next_task):
UnboundLocalError: local variable 'next_task' referenced before assignment

Linux-6.2.0-39-generic-x86_64-with-glibc2.35 x86_64
Ren'Py 8.1.3.23091805
DataVille 1.0
Sun Dec 31 19:59:37 2023
