I'm sorry, but an uncaught exception occurred.

While running game code:
  File "game/script.rpy", line 583, in script call
    call task_loop from _call_task_loop
  File "game/script.rpy", line 583, in script call
    call task_loop from _call_task_loop
  File "game/script.rpy", line 583, in script call
    call task_loop from _call_task_loop
  [Previous line repeated 2 more times]
  File "game/script.rpy", line 581, in script call
    call interstitial from _call_interstitial
  File "game/script.rpy", line 641, in script call
    call task_loop from _call_task_loop_1
  File "game/script.rpy", line 583, in script call
    call task_loop from _call_task_loop
  File "game/script.rpy", line 583, in script call
    call task_loop from _call_task_loop
  File "game/script.rpy", line 583, in script call
    call task_loop from _call_task_loop
  [Previous line repeated 6 more times]
  File "game/script.rpy", line 581, in script call
    call interstitial from _call_interstitial
  File "game/script.rpy", line 641, in script call
    call task_loop from _call_task_loop_1
  File "game/script.rpy", line 583, in script call
    call task_loop from _call_task_loop
  File "game/script.rpy", line 583, in script call
    call task_loop from _call_task_loop
  File "game/script.rpy", line 583, in script call
    call task_loop from _call_task_loop
  [Previous line repeated 6 more times]
  File "game/script.rpy", line 581, in script call
    call interstitial from _call_interstitial
  File "game/script.rpy", line 641, in script call
    call task_loop from _call_task_loop_1
  File "game/script.rpy", line 538, in script
    python:
  File "game/script.rpy", line 541, in <module>
    case = check_images(images_selected, task['correct_images'])
KeyError: 'correct_images'

-- Full Traceback ------------------------------------------------------------

Full traceback:
  File "game/script.rpy", line 583, in script call
    call task_loop from _call_task_loop
  File "game/script.rpy", line 583, in script call
    call task_loop from _call_task_loop
  File "game/script.rpy", line 583, in script call
    call task_loop from _call_task_loop
  [Previous line repeated 2 more times]
  File "game/script.rpy", line 581, in script call
    call interstitial from _call_interstitial
  File "game/script.rpy", line 641, in script call
    call task_loop from _call_task_loop_1
  File "game/script.rpy", line 583, in script call
    call task_loop from _call_task_loop
  File "game/script.rpy", line 583, in script call
    call task_loop from _call_task_loop
  File "game/script.rpy", line 583, in script call
    call task_loop from _call_task_loop
  [Previous line repeated 6 more times]
  File "game/script.rpy", line 581, in script call
    call interstitial from _call_interstitial
  File "game/script.rpy", line 641, in script call
    call task_loop from _call_task_loop_1
  File "game/script.rpy", line 583, in script call
    call task_loop from _call_task_loop
  File "game/script.rpy", line 583, in script call
    call task_loop from _call_task_loop
  File "game/script.rpy", line 583, in script call
    call task_loop from _call_task_loop
  [Previous line repeated 6 more times]
  File "game/script.rpy", line 581, in script call
    call interstitial from _call_interstitial
  File "game/script.rpy", line 641, in script call
    call task_loop from _call_task_loop_1
  File "game/script.rpy", line 538, in script
    python:
  File "/home/brent/dataville-renpy/renpy-8.1.3-sdk/renpy/ast.py", line 1138, in execute
    renpy.python.py_exec_bytecode(self.code.bytecode, self.hide, store=self.store)
  File "/home/brent/dataville-renpy/renpy-8.1.3-sdk/renpy/python.py", line 1122, in py_exec_bytecode
    exec(bytecode, globals, locals)
  File "game/script.rpy", line 541, in <module>
    case = check_images(images_selected, task['correct_images'])
KeyError: 'correct_images'

Linux-6.5.0-14-generic-x86_64-with-glibc2.35 x86_64
Ren'Py 8.1.3.23091805
DataVille 1.0
Tue Jan 23 15:38:03 2024
